5:return {{["y"] = 0, ["x"] = 0, ["name"] = "stairs:slab_mossycobble", ["z"] = 4, ["param2"] = 22, ["param1"] = 142}, {["y"] = 0, ["x"] = 0, ["name"] = "stairs:slab_mossycobble", ["z"] = 5, ["param2"] = 22, ["param1"] = 126}, {["y"] = 1, ["x"] = 0, ["name"] = "stairs:slab_mossycobble", ["z"] = 2, ["param2"] = 22, ["param1"] = 158}, {["y"] = 1, ["x"] = 0, ["name"] = "stairs:slab_mossycobble", ["z"] = 3, ["param2"] = 2, ["param1"] = 142}, {["y"] = 2, ["x"] = 0, ["name"] = "stairs:slab_mossycobble", ["z"] = 0, ["param2"] = 1, ["param1"] = 142}, {["y"] = 2, ["x"] = 0, ["name"] = "stairs:slab_mossycobble", ["z"] = 1, ["param2"] = 1, ["param1"] = 158}, {["y"] = 3, ["x"] = 0, ["name"] = "stairs:slab_goldblock", ["z"] = 4, ["param2"] = 22, ["param1"] = 158}, {["y"] = 3, ["x"] = 0, ["name"] = "stairs:slab_goldblock", ["z"] = 5, ["param2"] = 22, ["param1"] = 142}, {["y"] = 4, ["x"] = 0, ["name"] = "stairs:slab_goldblock", ["z"] = 2, ["param2"] = 22, ["param1"] = 174}, {["y"] = 4, ["x"] = 0, ["name"] = "stairs:slab_goldblock", ["z"] = 3, ["param2"] = 2, ["param1"] = 158}, {["y"] = 5, ["x"] = 0, ["name"] = "stairs:slab_goldblock", ["z"] = 0, ["param2"] = 1, ["param1"] = 142}, {["y"] = 5, ["x"] = 0, ["name"] = "stairs:slab_goldblock", ["z"] = 1, ["param2"] = 1, ["param1"] = 158}, {["y"] = 0, ["x"] = 1, ["name"] = "stairs:slab_mossycobble", ["z"] = 4, ["param2"] = 22, ["param1"] = 157}, {["y"] = 0, ["x"] = 1, ["name"] = "stairs:slab_mossycobble", ["z"] = 5, ["param2"] = 22, ["param1"] = 142}, {["y"] = 1, ["x"] = 1, ["name"] = "stairs:slab_mossycobble", ["z"] = 2, ["param2"] = 22, ["param1"] = 173}, {["y"] = 1, ["x"] = 1, ["name"] = "stairs:slab_mossycobble", ["z"] = 3, ["param2"] = 2, ["param1"] = 157}, {["y"] = 2, ["x"] = 1, ["name"] = "stairs:slab_mossycobble", ["z"] = 0, ["param2"] = 1, ["param1"] = 157}, {["y"] = 2, ["x"] = 1, ["name"] = "stairs:slab_mossycobble", ["z"] = 1, ["param2"] = 1, ["param1"] = 173}, {["y"] = 3, ["x"] = 1, ["name"] = "default:torch_wall", ["z"] = 2, ["param2"] = 2, ["param1"] = 205}, {["y"] = 3, ["x"] = 1, ["name"] = "stairs:slab_goldblock", ["z"] = 4, ["param2"] = 22, ["param1"] = 174}, {["y"] = 3, ["x"] = 1, ["name"] = "stairs:slab_goldblock", ["z"] = 5, ["param2"] = 22, ["param1"] = 158}, {["y"] = 4, ["x"] = 1, ["name"] = "stairs:slab_goldblock", ["z"] = 2, ["param2"] = 22, ["param1"] = 190}, {["y"] = 4, ["x"] = 1, ["name"] = "stairs:slab_goldblock", ["z"] = 3, ["param2"] = 2, ["param1"] = 174}, {["y"] = 5, ["x"] = 1, ["name"] = "stairs:slab_goldblock", ["z"] = 0, ["param2"] = 1, ["param1"] = 158}, {["y"] = 5, ["x"] = 1, ["name"] = "stairs:slab_goldblock", ["z"] = 1, ["param2"] = 1, ["param1"] = 174}, {["y"] = 0, ["x"] = 2, ["name"] = "default:goldblock", ["z"] = 2}, {["y"] = 0, ["x"] = 2, ["name"] = "default:mossycobble", ["z"] = 3}, {["y"] = 0, ["x"] = 2, ["name"] = "stairs:slab_mossycobble", ["z"] = 4, ["param2"] = 3, ["param1"] = 173}, {["y"] = 0, ["x"] = 2, ["name"] = "stairs:slab_mossycobble", ["z"] = 5, ["param2"] = 3, ["param1"] = 158}, {["y"] = 1, ["x"] = 2, ["name"] = "default:goldblock", ["z"] = 2}, {["y"] = 1, ["x"] = 2, ["name"] = "default:mossycobble", ["z"] = 3}, {["y"] = 2, ["x"] = 2, ["name"] = "stairs:slab_mossycobble", ["z"] = 0, ["param2"] = 21, ["param1"] = 172}, {["y"] = 2, ["x"] = 2, ["name"] = "stairs:slab_mossycobble", ["z"] = 1, ["param2"] = 21, ["param1"] = 188}, {["y"] = 2, ["x"] = 2, ["name"] = "default:goldblock", ["z"] = 2}, {["y"] = 2, ["x"] = 2, ["name"] = "default:mossycobble", ["z"] = 3}, {["y"] = 2, ["x"] = 2, ["name"] = "default:torch_wall", ["z"] = 4, ["param2"] = 5, ["param1"] = 205}, {["y"] = 3, ["x"] = 2, ["name"] = "default:goldblock", ["z"] = 2}, {["y"] = 3, ["x"] = 2, ["name"] = "default:mossycobble", ["z"] = 3}, {["y"] = 3, ["x"] = 2, ["name"] = "stairs:slab_goldblock", ["z"] = 4, ["param2"] = 3, ["param1"] = 189}, {["y"] = 3, ["x"] = 2, ["name"] = "stairs:slab_goldblock", ["z"] = 5, ["param2"] = 3, ["param1"] = 174}, {["y"] = 4, ["x"] = 2, ["name"] = "default:goldblock", ["z"] = 2}, {["y"] = 4, ["x"] = 2, ["name"] = "default:mossycobble", ["z"] = 3}, {["y"] = 5, ["x"] = 2, ["name"] = "stairs:slab_goldblock", ["z"] = 0, ["param2"] = 23, ["param1"] = 174}, {["y"] = 5, ["x"] = 2, ["name"] = "stairs:slab_goldblock", ["z"] = 1, ["param2"] = 23, ["param1"] = 190}, {["y"] = 5, ["x"] = 2, ["name"] = "default:goldblock", ["z"] = 2}, {["y"] = 5, ["x"] = 2, ["name"] = "default:mossycobble", ["z"] = 3}, {["y"] = 5, ["x"] = 2, ["name"] = "default:torch_wall", ["z"] = 4, ["param2"] = 5, ["param1"] = 206}, {["y"] = 6, ["x"] = 2, ["name"] = "default:obsidian_block", ["z"] = 2}, {["y"] = 6, ["x"] = 2, ["name"] = "default:obsidian_block", ["z"] = 3}, {["y"] = 6, ["x"] = 2, ["name"] = "stairs:slab_obsidian_block", ["z"] = 4, ["param2"] = 3, ["param1"] = 190}, {["y"] = 6, ["x"] = 2, ["name"] = "stairs:slab_obsidian_block", ["z"] = 5, ["param2"] = 3, ["param1"] = 174}, {["y"] = 0, ["x"] = 3, ["name"] = "stairs:slab_goldblock", ["z"] = 0, ["param1"] = 156}, {["y"] = 0, ["x"] = 3, ["name"] = "stairs:slab_goldblock", ["z"] = 1, ["param1"] = 172}, {["y"] = 0, ["x"] = 3, ["name"] = "default:goldblock", ["z"] = 2}, {["y"] = 0, ["x"] = 3, ["name"] = "default:mossycobble", ["z"] = 3}, {["y"] = 1, ["x"] = 3, ["name"] = "default:goldblock", ["z"] = 2}, {["y"] = 1, ["x"] = 3, ["name"] = "default:mossycobble", ["z"] = 3}, {["y"] = 2, ["x"] = 3, ["name"] = "default:torch_wall", ["z"] = 1, ["param2"] = 4, ["param1"] = 204}, {["y"] = 2, ["x"] = 3, ["name"] = "default:goldblock", ["z"] = 2}, {["y"] = 2, ["x"] = 3, ["name"] = "default:mossycobble", ["z"] = 3}, {["y"] = 2, ["x"] = 3, ["name"] = "stairs:slab_goldblock", ["z"] = 4, ["param2"] = 22, ["param1"] = 189}, {["y"] = 2, ["x"] = 3, ["name"] = "stairs:slab_goldblock", ["z"] = 5, ["param2"] = 22, ["param1"] = 174}, {["y"] = 3, ["x"] = 3, ["name"] = "stairs:slab_mossycobble", ["z"] = 0, ["param2"] = 3, ["param1"] = 173}, {["y"] = 3, ["x"] = 3, ["name"] = "stairs:slab_mossycobble", ["z"] = 1, ["param2"] = 3, ["param1"] = 189}, {["y"] = 3, ["x"] = 3, ["name"] = "default:goldblock", ["z"] = 2}, {["y"] = 3, ["x"] = 3, ["name"] = "default:mossycobble", ["z"] = 3}, {["y"] = 4, ["x"] = 3, ["name"] = "default:goldblock", ["z"] = 2}, {["y"] = 4, ["x"] = 3, ["name"] = "default:mossycobble", ["z"] = 3}, {["y"] = 5, ["x"] = 3, ["name"] = "default:torch_wall", ["z"] = 1, ["param2"] = 4, ["param1"] = 206}, {["y"] = 5, ["x"] = 3, ["name"] = "default:goldblock", ["z"] = 2}, {["y"] = 5, ["x"] = 3, ["name"] = "default:mossycobble", ["z"] = 3}, {["y"] = 5, ["x"] = 3, ["name"] = "stairs:slab_mossycobble", ["z"] = 4, ["param2"] = 21, ["param1"] = 190}, {["y"] = 5, ["x"] = 3, ["name"] = "stairs:slab_mossycobble", ["z"] = 5, ["param2"] = 21, ["param1"] = 174}, {["y"] = 6, ["x"] = 3, ["name"] = "stairs:slab_obsidian_block", ["z"] = 0, ["param2"] = 1, ["param1"] = 174}, {["y"] = 6, ["x"] = 3, ["name"] = "stairs:slab_obsidian_block", ["z"] = 1, ["param2"] = 1, ["param1"] = 190}, {["y"] = 6, ["x"] = 3, ["name"] = "default:obsidian_block", ["z"] = 2}, {["y"] = 6, ["x"] = 3, ["name"] = "default:obsidian_block", ["z"] = 3}, {["y"] = 0, ["x"] = 4, ["name"] = "stairs:slab_goldblock", ["z"] = 0, ["param2"] = 20, ["param1"] = 141}, {["y"] = 0, ["x"] = 4, ["name"] = "stairs:slab_goldblock", ["z"] = 1, ["param2"] = 20, ["param1"] = 157}, {["y"] = 1, ["x"] = 4, ["name"] = "stairs:slab_goldblock", ["z"] = 2, ["param1"] = 157}, {["y"] = 1, ["x"] = 4, ["name"] = "stairs:slab_goldblock", ["z"] = 3, ["param2"] = 20, ["param1"] = 173}, {["y"] = 2, ["x"] = 4, ["name"] = "stairs:slab_goldblock", ["z"] = 4, ["param2"] = 3, ["param1"] = 173}, {["y"] = 2, ["x"] = 4, ["name"] = "stairs:slab_goldblock", ["z"] = 5, ["param2"] = 3, ["param1"] = 158}, {["y"] = 3, ["x"] = 4, ["name"] = "stairs:slab_mossycobble", ["z"] = 0, ["param2"] = 20, ["param1"] = 158}, {["y"] = 3, ["x"] = 4, ["name"] = "stairs:slab_mossycobble", ["z"] = 1, ["param2"] = 20, ["param1"] = 174}, {["y"] = 3, ["x"] = 4, ["name"] = "default:torch_wall", ["z"] = 3, ["param2"] = 3, ["param1"] = 205}, {["y"] = 4, ["x"] = 4, ["name"] = "stairs:slab_mossycobble", ["z"] = 2, ["param2"] = 2, ["param1"] = 174}, {["y"] = 4, ["x"] = 4, ["name"] = "stairs:slab_mossycobble", ["z"] = 3, ["param2"] = 21, ["param1"] = 190}, {["y"] = 5, ["x"] = 4, ["name"] = "stairs:slab_mossycobble", ["z"] = 4, ["param2"] = 2, ["param1"] = 174}, {["y"] = 5, ["x"] = 4, ["name"] = "stairs:slab_mossycobble", ["z"] = 5, ["param2"] = 2, ["param1"] = 158}, {["y"] = 0, ["x"] = 5, ["name"] = "stairs:slab_goldblock", ["z"] = 0, ["param2"] = 20, ["param1"] = 126}, {["y"] = 0, ["x"] = 5, ["name"] = "stairs:slab_goldblock", ["z"] = 1, ["param2"] = 20, ["param1"] = 142}, {["y"] = 1, ["x"] = 5, ["name"] = "stairs:slab_goldblock", ["z"] = 2, ["param1"] = 142}, {["y"] = 1, ["x"] = 5, ["name"] = "stairs:slab_goldblock", ["z"] = 3, ["param2"] = 20, ["param1"] = 158}, {["y"] = 2, ["x"] = 5, ["name"] = "stairs:slab_goldblock", ["z"] = 4, ["param2"] = 3, ["param1"] = 158}, {["y"] = 2, ["x"] = 5, ["name"] = "stairs:slab_goldblock", ["z"] = 5, ["param2"] = 3, ["param1"] = 142}, {["y"] = 3, ["x"] = 5, ["name"] = "stairs:slab_mossycobble", ["z"] = 0, ["param2"] = 20, ["param1"] = 142}, {["y"] = 3, ["x"] = 5, ["name"] = "stairs:slab_mossycobble", ["z"] = 1, ["param2"] = 20, ["param1"] = 158}, {["y"] = 4, ["x"] = 5, ["name"] = "stairs:slab_mossycobble", ["z"] = 2, ["param2"] = 2, ["param1"] = 158}, {["y"] = 4, ["x"] = 5, ["name"] = "stairs:slab_mossycobble", ["z"] = 3, ["param2"] = 21, ["param1"] = 174}, {["y"] = 5, ["x"] = 5, ["name"] = "stairs:slab_mossycobble", ["z"] = 4, ["param2"] = 2, ["param1"] = 158}, {["y"] = 5, ["x"] = 5, ["name"] = "stairs:slab_mossycobble", ["z"] = 5, ["param2"] = 2, ["param1"] = 142}}